{"trial_id": "0", "hyperparameters": {"space": [{"class_name": "Int", "config": {"name": "neurons", "default": null, "conditions": [], "min_value": 8, "max_value": 32, "step": 8, "sampling": "linear"}}, {"class_name": "Int", "config": {"name": "filters", "default": null, "conditions": [], "min_value": 32, "max_value": 128, "step": 32, "sampling": "linear"}}, {"class_name": "Choice", "config": {"name": "learning_rate", "default": 0.1, "conditions": [], "values": [0.1, 0.01, 0.001], "ordered": true}}, {"class_name": "Choice", "config": {"name": "batch_size", "default": 10, "conditions": [], "values": [10, 20, 32], "ordered": true}}], "values": {"neurons": 16, "filters": 128, "learning_rate": 0.1, "batch_size": 20}}, "metrics": {"metrics": {}}, "score": null, "best_step": 0, "status": "FAILED", "message": "Traceback (most recent call last):\n  File \"h:\\nlp\\.venv\\Lib\\site-packages\\keras_tuner\\src\\engine\\base_tuner.py\", line 274, in _try_run_and_update_trial\n    self._run_and_update_trial(trial, *fit_args, **fit_kwargs)\n  File \"h:\\nlp\\.venv\\Lib\\site-packages\\keras_tuner\\src\\engine\\base_tuner.py\", line 239, in _run_and_update_trial\n    results = self.run_trial(trial, *fit_args, **fit_kwargs)\n              ^^^^^^^^^^^^^^^^^^^^^^^^^^^^^^^^^^^^^^^^^^^^^^\n  File \"h:\\nlp\\.venv\\Lib\\site-packages\\keras_tuner\\src\\engine\\tuner.py\", line 314, in run_trial\n    obj_value = self._build_and_fit_model(trial, *args, **copied_kwargs)\n                ^^^^^^^^^^^^^^^^^^^^^^^^^^^^^^^^^^^^^^^^^^^^^^^^^^^^^^^^\n  File \"h:\\nlp\\.venv\\Lib\\site-packages\\keras_tuner\\src\\engine\\tuner.py\", line 233, in _build_and_fit_model\n    results = self.hypermodel.fit(hp, model, *args, **kwargs)\n              ^^^^^^^^^^^^^^^^^^^^^^^^^^^^^^^^^^^^^^^^^^^^^^^\n  File \"h:\\nlp\\.venv\\Lib\\site-packages\\keras_tuner\\src\\engine\\hypermodel.py\", line 149, in fit\n    return model.fit(*args, **kwargs)\n           ^^^^^^^^^^^^^^^^^^^^^^^^^^\n  File \"h:\\nlp\\.venv\\Lib\\site-packages\\keras\\src\\utils\\traceback_utils.py\", line 122, in error_handler\n    raise e.with_traceback(filtered_tb) from None\n  File \"h:\\nlp\\.venv\\Lib\\site-packages\\keras\\src\\utils\\traceback_utils.py\", line 124, in error_handler\n    del filtered_tb\n        ^^^^^^^^^^^\nValueError: Exception encountered when calling Conv2D.call().\n\n\u001b[1mNegative dimension size caused by subtracting 4 from 1 for '{{node sequential_1/conv2d_1_2/convolution}} = Conv2D[T=DT_FLOAT, data_format=\"NHWC\", dilations=[1, 1, 1, 1], explicit_paddings=[], padding=\"VALID\", strides=[1, 2, 2, 1], use_cudnn_on_gpu=true](sequential_1/max_pooling2d_1/MaxPool2d, sequential_1/conv2d_1_2/convolution/ReadVariableOp)' with input shapes: [?,7,1,128], [4,4,128,16].\u001b[0m\n\nArguments received by Conv2D.call():\n  \u2022 inputs=tf.Tensor(shape=(None, 7, 1, 128), dtype=float32)\n"}